<?xml version="1.0" encoding="utf-8"?>
<!-- This URDF was automatically created by SolidWorks to URDF Exporter! Originally created by Stephen Brawner (brawner@gmail.com) 
     Commit Version: 1.6.0-1-g15f4949  Build Version: 1.6.7594.29634
     For more information, please see http://wiki.ros.org/sw_urdf_exporter -->
<robot
  name="tennisbot_support">

  <link name="base_footprint"/>

  <joint name="base_joint" type="fixed">
    <parent link="base_footprint"/>
    <child link="base_link"/>
    <origin xyz="0.0 0.0 -0.162692660283703" rpy="-1.57 0 0"/>
  </joint>

  <link
    name="base_link">
    <inertial>
      <origin
        xyz="0.104659789395195 -0.196207572672501 0.162692660283703"
        rpy="0 0 0" />
      <mass
        value="1.15520000000003" />
      <inertia
        ixx="0.0101215048568796"
        ixy="5.16525795195962E-17"
        ixz="-1.00415010343757E-15"
        iyy="0.0166361512568799"
        iyz="-8.8233065927587E-17"
        izz="0.00682269973333366" />
    </inertial>
    <visual>
      <origin
        xyz="0 0 0"
        rpy="0 0 0" />
      <geometry>
        <mesh
          filename="package://tennisbot_support/meshes/base_link.STL" />
      </geometry>
      <material
        name="">
        <color
          rgba="0.494117647058824 0.494117647058824 0.525490196078431 1" />
      </material>
    </visual>
    <collision>
      <origin
        xyz="0 0 0"
        rpy="0 0 0" />
      <geometry>
        <mesh
          filename="package://tennisbot_support/meshes/base_link.STL" />
      </geometry>
    </collision>
  </link>
  <link
    name="mount_link">
    <inertial>
      <origin
        xyz="4.7805584491023E-10 1.61652830010794E-10 4.26778057338595E-11"
        rpy="0 0 0" />
      <mass
        value="0.744243099298161" />
      <inertia
        ixx="0.00113617129627213"
        ixy="-5.31586880855191E-09"
        ixz="5.94695384178492E-10"
        iyy="0.00541459267764306"
        iyz="4.45684694076088E-05"
        izz="0.00499820875614038" />
    </inertial>
    <visual>
      <origin
        xyz="0 0 0"
        rpy="0 0 0" />
      <geometry>
        <mesh
          filename="package://tennisbot_support/meshes/mount_link.STL" />
      </geometry>
      <material
        name="">
        <color
          rgba="0.494117647058824 0.494117647058824 0.525490196078431 1" />
      </material>
    </visual>
    <collision>
      <origin
        xyz="0 0 0"
        rpy="0 0 0" />
      <geometry>
        <mesh
          filename="package://tennisbot_support/meshes/mount_link.STL" />
      </geometry>
    </collision>
  </link>
  <joint
    name="mount_joint"
    type="fixed">
    <origin
      xyz="0.104659809442308 -0.266871907624069 0.0733480237700171"
      rpy="-1.5707963267949 0 -3.14159265358979" />
    <parent
      link="base_link" />
    <child
      link="mount_link" />
    <axis
      xyz="0 0 0" />
  </joint>
  <link
    name="pipe_link">
    <inertial>
      <origin
        xyz="0.00896336722335153 0.125428985340103 6.43253882881556E-07"
        rpy="0 0 0" />
      <mass
        value="0.33490980168325" />
      <inertia
        ixx="0.00233036766489112"
        ixy="-2.23683208598698E-05"
        ixz="3.26297088153394E-08"
        iyy="0.000666584643212901"
        iyz="-2.27417937656625E-09"
        izz="0.00231739505538052" />
    </inertial>
    <visual>
      <origin
        xyz="0 0 0"
        rpy="0 0 0" />
      <geometry>
        <mesh
          filename="package://tennisbot_support/meshes/pipe_link.STL" />
      </geometry>
      <material
        name="">
        <color
          rgba="0.494117647058824 0.494117647058824 0.525490196078431 1" />
      </material>
    </visual>
    <collision>
      <origin
        xyz="0 0 0"
        rpy="0 0 0" />
      <geometry>
        <mesh
          filename="package://tennisbot_support/meshes/pipe_link.STL" />
      </geometry>
    </collision>
  </link>
  <joint
    name="pipe_joint"
    type="continuous">
    <origin
      xyz="0 -0.00131139551645104 0.0238356650484354"
      rpy="0 0 3.14159265358979" />
    <parent
      link="mount_link" />
    <child
      link="pipe_link" />
    <axis
      xyz="1 0 0" />
  </joint>
  <link
    name="top_wheel_link">
    <inertial>
      <origin
        xyz="-0.00100002004712066 1.11022302462516E-16 0"
        rpy="0 0 0" />
      <mass
        value="0.328195901335219" />
      <inertia
        ixx="0.000334923917312591"
        ixy="-2.8951321439356E-21"
        ixz="1.98595160072015E-37"
        iyy="0.000241415435090498"
        iyz="1.90864757447969E-20"
        izz="0.000241415435090498" />
    </inertial>
    <visual>
      <origin
        xyz="0 0 0"
        rpy="0 0 0" />
      <geometry>
        <mesh
          filename="package://tennisbot_support/meshes/top_wheel_link.STL" />
      </geometry>
      <material
        name="">
        <color
          rgba="0.494117647058824 0.494117647058824 0.525490196078431 1" />
      </material>
    </visual>
    <collision>
      <origin
        xyz="0 0 0"
        rpy="0 0 0" />
      <geometry>
        <mesh
          filename="package://tennisbot_support/meshes/top_wheel_link.STL" />
      </geometry>
    </collision>
  </link>
  <joint
    name="top_wheel_joint"
    type="continuous">
    <origin
      xyz="0 0.135000000000007 0.0729999999999982"
      rpy="0 0 0" />
    <parent
      link="pipe_link" />
    <child
      link="top_wheel_link" />
    <axis
      xyz="1 0 0" />
  </joint>
  <link
    name="bot_wheel_link">
    <inertial>
      <origin
        xyz="-0.00100002004712063 1.11022302462516E-16 -2.77555756156289E-17"
        rpy="0 0 0" />
      <mass
        value="0.328195901335218" />
      <inertia
        ixx="0.00033492391731259"
        ixy="5.16987882845613E-24"
        ixz="0"
        iyy="0.000241415435090498"
        iyz="-6.16639985601131E-20"
        izz="0.000241415435090498" />
    </inertial>
    <visual>
      <origin
        xyz="0 0 0"
        rpy="0 0 0" />
      <geometry>
        <mesh
          filename="package://tennisbot_support/meshes/bot_wheel_link.STL" />
      </geometry>
      <material
        name="">
        <color
          rgba="0.494117647058824 0.494117647058824 0.525490196078431 1" />
      </material>
    </visual>
    <collision>
      <origin
        xyz="0 0 0"
        rpy="0 0 0" />
      <geometry>
        <mesh
          filename="package://tennisbot_support/meshes/bot_wheel_link.STL" />
      </geometry>
    </collision>
  </link>
  <joint
    name="bot_wheel_joint"
    type="continuous">
    <origin
      xyz="0 0.135000000000007 -0.0730000000000018"
      rpy="0 0 0" />
    <parent
      link="pipe_link" />
    <child
      link="bot_wheel_link" />
    <axis
      xyz="1 0 0" />
  </joint>
  <link
    name="top_trigger_link">
    <inertial>
      <origin
        xyz="4.69069227904129E-15 0.0206229180482504 -2.00471154815363E-08"
        rpy="0 0 0" />
      <mass
        value="0.00556274333882309" />
      <inertia
        ixx="1.09230824358136E-06"
        ixy="1.01134519225253E-20"
        ixz="1.08213016457071E-22"
        iyy="1.14169402076655E-07"
        iyz="1.15899847888608E-22"
        izz="1.11376525667763E-06" />
    </inertial>
    <visual>
      <origin
        xyz="0 0 0"
        rpy="0 0 0" />
      <geometry>
        <mesh
          filename="package://tennisbot_support/meshes/top_trigger_link.STL" />
      </geometry>
      <material
        name="">
        <color
          rgba="0.494117647058824 0.494117647058824 0.525490196078431 1" />
      </material>
    </visual>
    <collision>
      <origin
        xyz="0 0 0"
        rpy="0 0 0" />
      <geometry>
        <mesh
          filename="package://tennisbot_support/meshes/top_trigger_link.STL" />
      </geometry>
    </collision>
  </link>
  <joint
    name="top_trigger_joint"
    type="continuous">
    <origin
      xyz="0 0.0423000000000067 0.0489999999999982"
      rpy="-1.57079632679491 0 -1.5707963267949" />
    <parent
      link="pipe_link" />
    <child
      link="top_trigger_link" />
    <axis
      xyz="0 0 1" />
  </joint>
  <link
    name="bot_trigger_link">
    <inertial>
      <origin
        xyz="3.66373598126302E-15 0.0206229180482504 -2.00471244188316E-08"
        rpy="0 0 0" />
      <mass
        value="0.00556274333882308" />
      <inertia
        ixx="1.09230824358135E-06"
        ixy="2.8824254188511E-21"
        ixz="-6.88875669628211E-23"
        iyy="1.14169402076654E-07"
        iyz="1.80420167957529E-22"
        izz="1.11376525667762E-06" />
    </inertial>
    <visual>
      <origin
        xyz="0 0 0"
        rpy="0 0 0" />
      <geometry>
        <mesh
          filename="package://tennisbot_support/meshes/bot_trigger_link.STL" />
      </geometry>
      <material
        name="">
        <color
          rgba="0.494117647058824 0.494117647058824 0.525490196078431 1" />
      </material>
    </visual>
    <collision>
      <origin
        xyz="0 0 0"
        rpy="0 0 0" />
      <geometry>
        <mesh
          filename="package://tennisbot_support/meshes/bot_trigger_link.STL" />
      </geometry>
    </collision>
  </link>
  <joint
    name="bot_trigger_joint"
    type="continuous">
    <origin
      xyz="0 0.0423000000000067 -0.0490000000000018"
      rpy="1.57079632679488 0 1.5707963267949" />
    <parent
      link="pipe_link" />
    <child
      link="bot_trigger_link" />
    <axis
      xyz="0 0 1" />
  </joint>
</robot>